<?xml version="1.0" ?>
<robot name="Robot" xmlns:xacro="http://www.ros.org/wiki/xacro">

<xacro:include filename="$(find Robot_description)/urdf/materials.xacro" />
<xacro:include filename="$(find Robot_description)/urdf/Robot.trans" />
<xacro:include filename="$(find Robot_description)/urdf/Robot.gazebo" />

<link name="base_link">
  <inertial>
    <origin xyz="-5.4625582770534356e-17 -8.875567850903196e-16 -0.0037505118526864737" rpy="0 0 0"/>
    <mass value="4.60049562929677"/>
    <inertia ixx="0.033068" iyy="0.072424" izz="0.099524" ixy="-0.0" iyz="0.0" ixz="0.0"/>
  </inertial>
  <visual>
    <origin xyz="0 0 0" rpy="0 0 0"/>
    <geometry>
      <mesh filename="package://Robot_description/meshes/base_link.stl" scale="0.001 0.001 0.001"/>
    </geometry>
    <material name="silver"/>
  </visual>
  <collision>
    <origin xyz="0 0 0" rpy="0 0 0"/>
    <geometry>
      <mesh filename="package://Robot_description/meshes/base_link.stl" scale="0.001 0.001 0.001"/>
    </geometry>
  </collision>
</link>

<link name="IMU_1">
  <inertial>
    <origin xyz="0.025 -0 0.008" rpy="0 0 0"/>
    <mass value="0.0516"/>
    <inertia ixx="3e-06" iyy="4e-06" izz="6e-06" ixy="0.0" iyz="0.0" ixz="-0.0"/>
  </inertial>
  <visual>
    <origin xyz="-0.0 -0.0 -0.004" rpy="0 0 0"/>
    <geometry>
      <mesh filename="package://Robot_description/meshes/IMU_1.stl" scale="0.001 0.001 0.001"/>
    </geometry>
    <material name="red"/>
  </visual>
  <collision>
    <origin xyz="-0.0 -0.0 -0.004" rpy="0 0 0"/>
    <geometry>
      <mesh filename="package://Robot_description/meshes/IMU_1.stl" scale="0.001 0.001 0.001"/>
    </geometry>
  </collision>
</link>

<link name="Jetson_1">
  <inertial>
    <origin xyz="-0.037665 -0 0.012" rpy="0 0 0"/>
    <mass value="0.25"/>
    <inertia ixx="0.000144" iyy="0.000123" izz="0.000249" ixy="-1.7e-05" iyz="-1e-06" ixz="-1.2e-05"/>
  </inertial>
  <visual>
    <origin xyz="-0.0 -0.0 -0.004" rpy="0 0 0"/>
    <geometry>
      <mesh filename="package://Robot_description/meshes/Jetson_1.stl" scale="0.001 0.001 0.001"/>
    </geometry>
    <material name="red"/>
  </visual>
  <collision>
    <origin xyz="-0.0 -0.0 -0.004" rpy="0 0 0"/>
    <geometry>
      <mesh filename="package://Robot_description/meshes/Jetson_1.stl" scale="0.001 0.001 0.001"/>
    </geometry>
  </collision>
</link>

<link name="Lidar_1">
  <inertial>
    <origin xyz="-0.000 0 0.065131" rpy="0 0 0"/>
    <mass value="0.17"/>
    <inertia ixx="0.000431" iyy="0.000759" izz="0.000786" ixy="-4e-06" iyz="5e-06" ixz="4.6e-05"/>
  </inertial>
  <visual>
    <origin xyz="-0.0 -0.0 -0.038" rpy="0 0 0"/>
    <geometry>
      <mesh filename="package://Robot_description/meshes/Lidar_1.stl" scale="0.001 0.001 0.001"/>
    </geometry>
    <material name="green"/>
  </visual>
  <collision>
    <origin xyz="-0.0 -0.0 -0.038" rpy="0 0 0"/>
    <geometry>
      <mesh filename="package://Robot_description/meshes/Lidar_1.stl" scale="0.001 0.001 0.001"/>
    </geometry>
  </collision>
</link>


<joint name="IMU_joint" type="fixed">
  <origin xyz="0.0 0.0 0.004" rpy="0 0 0"/>
  <parent link="base_link"/>
  <child link="IMU_1"/>
</joint>

<joint name="Jetson_joint" type="fixed">
  <origin xyz="0.0 0.0 0.004" rpy="0 0 0"/>
  <parent link="base_link"/>
  <child link="Jetson_1"/>
</joint>

<joint name="Lidar_joint" type="fixed">
  <origin xyz="0.0 0.0 0.038" rpy="0 0 0"/>
  <parent link="base_link"/>
  <child link="Lidar_1"/>
</joint>



<link name="TL_R1_1">
  <inertial>
    <origin xyz="-0.014392879792441568 -0.016619499101653917 -0.008309671781580983" rpy="0 0 0"/>
    <mass value="0.07897141474580414"/>
    <inertia ixx="9e-06" iyy="8e-06" izz="1.2e-05" ixy="-4e-06" iyz="-2e-06" ixz="-2e-06"/>
  </inertial>
  <visual>
    <origin xyz="-0.126757 -0.176678 -0.017191" rpy="0 0 0"/>
    <geometry>
      <mesh filename="package://Robot_description/meshes/TL_R1_1.stl" scale="0.001 0.001 0.001"/>
    </geometry>
    <material name="black"/>
  </visual>
  <collision>
    <origin xyz="-0.126757 -0.176678 -0.017191" rpy="0 0 0"/>
    <geometry>
      <mesh filename="package://Robot_description/meshes/TL_R1_1.stl" scale="0.001 0.001 0.001"/>
    </geometry>
  </collision>
</link>

<link name="TL_R2_1">
  <inertial>
    <origin xyz="-0.016366693234100255 -0.016619499101663326 0.0028857416909925156" rpy="0 0 0"/>
    <mass value="0.078971414745804"/>
    <inertia ixx="8e-06" iyy="8e-06" izz="1.3e-05" ixy="-5e-06" iyz="1e-06" ixz="1e-06"/>
  </inertial>
  <visual>
    <origin xyz="-0.155863 -0.176678 -0.010778" rpy="0 0 0"/>
    <geometry>
      <mesh filename="package://Robot_description/meshes/TL_R2_1.stl" scale="0.001 0.001 0.001"/>
    </geometry>
    <material name="black"/>
  </visual>
  <collision>
    <origin xyz="-0.155863 -0.176678 -0.010778" rpy="0 0 0"/>
    <geometry>
      <mesh filename="package://Robot_description/meshes/TL_R2_1.stl" scale="0.001 0.001 0.001"/>
    </geometry>
  </collision>
</link>

<link name="TL_R3_1">
  <inertial>
    <origin xyz="-0.010682156366847245 -0.016619499101691776 0.012731049612975462" rpy="0 0 0"/>
    <mass value="0.07897141474580419"/>
    <inertia ixx="1.1e-05" iyy="8e-06" izz="1e-05" ixy="-3e-06" iyz="4e-06" ixz="2e-06"/>
  </inertial>
  <visual>
    <origin xyz="-0.174037 -0.176678 0.012844" rpy="0 0 0"/>
    <geometry>
      <mesh filename="package://Robot_description/meshes/TL_R3_1.stl" scale="0.001 0.001 0.001"/>
    </geometry>
    <material name="black"/>
  </visual>
  <collision>
    <origin xyz="-0.174037 -0.176678 0.012844" rpy="0 0 0"/>
    <geometry>
      <mesh filename="package://Robot_description/meshes/TL_R3_1.stl" scale="0.001 0.001 0.001"/>
    </geometry>
  </collision>
</link>

<link name="TL_R4_1">
  <inertial>
    <origin xyz="5.625105456430468e-08 -0.016619499101712537 0.01661851931853145" rpy="0 0 0"/>
    <mass value="0.07897141474580414"/>
    <inertia ixx="1.3e-05" iyy="8e-06" izz="8e-06" ixy="-0.0" iyz="5e-06" ixz="-0.0"/>
  </inertial>
  <visual>
    <origin xyz="-0.172776 -0.176678 0.042621" rpy="0 0 0"/>
    <geometry>
      <mesh filename="package://Robot_description/meshes/TL_R4_1.stl" scale="0.001 0.001 0.001"/>
    </geometry>
    <material name="black"/>
  </visual>
  <collision>
    <origin xyz="-0.172776 -0.176678 0.042621" rpy="0 0 0"/>
    <geometry>
      <mesh filename="package://Robot_description/meshes/TL_R4_1.stl" scale="0.001 0.001 0.001"/>
    </geometry>
  </collision>
</link>

<link name="TL_R5_1">
  <inertial>
    <origin xyz="0.010682654530559915 -0.016619499101727803 0.01273114976251112" rpy="0 0 0"/>
    <mass value="0.07897141474580416"/>
    <inertia ixx="1.1e-05" iyy="8e-06" izz="1e-05" ixy="3e-06" iyz="4e-06" ixz="-2e-06"/>
  </inertial>
  <visual>
    <origin xyz="-0.152669 -0.176678 0.064622" rpy="0 0 0"/>
    <geometry>
      <mesh filename="package://Robot_description/meshes/TL_R5_1.stl" scale="0.001 0.001 0.001"/>
    </geometry>
    <material name="black"/>
  </visual>
  <collision>
    <origin xyz="-0.152669 -0.176678 0.064622" rpy="0 0 0"/>
    <geometry>
      <mesh filename="package://Robot_description/meshes/TL_R5_1.stl" scale="0.001 0.001 0.001"/>
    </geometry>
  </collision>
</link>

<link name="TL_R6_1">
  <inertial>
    <origin xyz="0.016366420777257404 -0.016619499101731855 0.0028853967773264516" rpy="0 0 0"/>
    <mass value="0.07897141474580448"/>
    <inertia ixx="8e-06" iyy="8e-06" izz="1.3e-05" ixy="5e-06" iyz="1e-06" ixz="-1e-06"/>
  </inertial>
  <visual>
    <origin xyz="-0.123125 -0.176678 0.06855" rpy="0 0 0"/>
    <geometry>
      <mesh filename="package://Robot_description/meshes/TL_R6_1.stl" scale="0.001 0.001 0.001"/>
    </geometry>
    <material name="black"/>
  </visual>
  <collision>
    <origin xyz="-0.123125 -0.176678 0.06855" rpy="0 0 0"/>
    <geometry>
      <mesh filename="package://Robot_description/meshes/TL_R6_1.stl" scale="0.001 0.001 0.001"/>
    </geometry>
  </collision>
</link>

<link name="TL_R7_1">
  <inertial>
    <origin xyz="0.01439282354125744 -0.016619499101707874 -0.008309847537017988" rpy="0 0 0"/>
    <mass value="0.07897141474580424"/>
    <inertia ixx="9e-06" iyy="8e-06" izz="1.2e-05" ixy="4e-06" iyz="-2e-06" ixz="2e-06"/>
  </inertial>
  <visual>
    <origin xyz="-0.097967 -0.176678 0.052569" rpy="0 0 0"/>
    <geometry>
      <mesh filename="package://Robot_description/meshes/TL_R7_1.stl" scale="0.001 0.001 0.001"/>
    </geometry>
    <material name="black"/>
  </visual>
  <collision>
    <origin xyz="-0.097967 -0.176678 0.052569" rpy="0 0 0"/>
    <geometry>
      <mesh filename="package://Robot_description/meshes/TL_R7_1.stl" scale="0.001 0.001 0.001"/>
    </geometry>
  </collision>
</link>

<link name="TL_R8_1">
  <inertial>
    <origin xyz="0.0056840387034130385 -0.016619499101683616 -0.015616891453574356" rpy="0 0 0"/>
    <mass value="0.07897141474580432"/>
    <inertia ixx="1.2e-05" iyy="8e-06" izz="9e-06" ixy="2e-06" iyz="-4e-06" ixz="1e-06"/>
  </inertial>
  <visual>
    <origin xyz="-0.088968 -0.176678 0.024156" rpy="0 0 0"/>
    <geometry>
      <mesh filename="package://Robot_description/meshes/TL_R8_1.stl" scale="0.001 0.001 0.001"/>
    </geometry>
    <material name="black"/>
  </visual>
  <collision>
    <origin xyz="-0.088968 -0.176678 0.024156" rpy="0 0 0"/>
    <geometry>
      <mesh filename="package://Robot_description/meshes/TL_R8_1.stl" scale="0.001 0.001 0.001"/>
    </geometry>
  </collision>
</link>

<link name="TL_R9_1">
  <inertial>
    <origin xyz="-0.005684264410537904 -0.016619499101666046 -0.015616446390367146" rpy="0 0 0"/>
    <mass value="0.07897141474580434"/>
    <inertia ixx="1.2e-05" iyy="8e-06" izz="9e-06" ixy="-2e-06" iyz="-4e-06" ixz="-1e-06"/>
  </inertial>
  <visual>
    <origin xyz="-0.100338 -0.176678 -0.003394" rpy="0 0 0"/>
    <geometry>
      <mesh filename="package://Robot_description/meshes/TL_R9_1.stl" scale="0.001 0.001 0.001"/>
    </geometry>
    <material name="black"/>
  </visual>
  <collision>
    <origin xyz="-0.100338 -0.176678 -0.003394" rpy="0 0 0"/>
    <geometry>
      <mesh filename="package://Robot_description/meshes/TL_R9_1.stl" scale="0.001 0.001 0.001"/>
    </geometry>
  </collision>
</link>

<link name="BR_R1_1">
  <inertial>
    <origin xyz="-0.005684038703413052 0.016619499101683533 -0.015616891453574349" rpy="0 0 0"/>
    <mass value="0.07897141474580432"/>
    <inertia ixx="1.2e-05" iyy="8e-06" izz="9e-06" ixy="2e-06" iyz="4e-06" ixz="-1e-06"/>
  </inertial>
  <visual>
    <origin xyz="0.088968 0.176678 0.024156" rpy="0 0 0"/>
    <geometry>
      <mesh filename="package://Robot_description/meshes/BR_R1_1.stl" scale="0.001 0.001 0.001"/>
    </geometry>
    <material name="black"/>
  </visual>
  <collision>
    <origin xyz="0.088968 0.176678 0.024156" rpy="0 0 0"/>
    <geometry>
      <mesh filename="package://Robot_description/meshes/BR_R1_1.stl" scale="0.001 0.001 0.001"/>
    </geometry>
  </collision>
</link>

<link name="BR_R2_1">
  <inertial>
    <origin xyz="-0.014392823541257455 0.016619499101707846 -0.008309847537017988" rpy="0 0 0"/>
    <mass value="0.07897141474580424"/>
    <inertia ixx="9e-06" iyy="8e-06" izz="1.2e-05" ixy="4e-06" iyz="2e-06" ixz="-2e-06"/>
  </inertial>
  <visual>
    <origin xyz="0.097967 0.176678 0.052569" rpy="0 0 0"/>
    <geometry>
      <mesh filename="package://Robot_description/meshes/BR_R2_1.stl" scale="0.001 0.001 0.001"/>
    </geometry>
    <material name="black"/>
  </visual>
  <collision>
    <origin xyz="0.097967 0.176678 0.052569" rpy="0 0 0"/>
    <geometry>
      <mesh filename="package://Robot_description/meshes/BR_R2_1.stl" scale="0.001 0.001 0.001"/>
    </geometry>
  </collision>
</link>

<link name="BR_R3_1">
  <inertial>
    <origin xyz="-0.016366420777257404 0.016619499101731827 0.0028853967773264516" rpy="0 0 0"/>
    <mass value="0.07897141474580448"/>
    <inertia ixx="8e-06" iyy="8e-06" izz="1.3e-05" ixy="5e-06" iyz="-1e-06" ixz="1e-06"/>
  </inertial>
  <visual>
    <origin xyz="0.123125 0.176678 0.06855" rpy="0 0 0"/>
    <geometry>
      <mesh filename="package://Robot_description/meshes/BR_R3_1.stl" scale="0.001 0.001 0.001"/>
    </geometry>
    <material name="black"/>
  </visual>
  <collision>
    <origin xyz="0.123125 0.176678 0.06855" rpy="0 0 0"/>
    <geometry>
      <mesh filename="package://Robot_description/meshes/BR_R3_1.stl" scale="0.001 0.001 0.001"/>
    </geometry>
  </collision>
</link>

<link name="BR_R4_1">
  <inertial>
    <origin xyz="-0.010682654530559915 0.016619499101727775 0.01273114976251112" rpy="0 0 0"/>
    <mass value="0.07897141474580416"/>
    <inertia ixx="1.1e-05" iyy="8e-06" izz="1e-05" ixy="3e-06" iyz="-4e-06" ixz="2e-06"/>
  </inertial>
  <visual>
    <origin xyz="0.152669 0.176678 0.064622" rpy="0 0 0"/>
    <geometry>
      <mesh filename="package://Robot_description/meshes/BR_R4_1.stl" scale="0.001 0.001 0.001"/>
    </geometry>
    <material name="black"/>
  </visual>
  <collision>
    <origin xyz="0.152669 0.176678 0.064622" rpy="0 0 0"/>
    <geometry>
      <mesh filename="package://Robot_description/meshes/BR_R4_1.stl" scale="0.001 0.001 0.001"/>
    </geometry>
  </collision>
</link>

<link name="BR_R5_1">
  <inertial>
    <origin xyz="-5.625105456430468e-08 0.01661949910171248 0.01661851931853146" rpy="0 0 0"/>
    <mass value="0.07897141474580414"/>
    <inertia ixx="1.3e-05" iyy="8e-06" izz="8e-06" ixy="-0.0" iyz="-5e-06" ixz="0.0"/>
  </inertial>
  <visual>
    <origin xyz="0.172776 0.176678 0.042621" rpy="0 0 0"/>
    <geometry>
      <mesh filename="package://Robot_description/meshes/BR_R5_1.stl" scale="0.001 0.001 0.001"/>
    </geometry>
    <material name="black"/>
  </visual>
  <collision>
    <origin xyz="0.172776 0.176678 0.042621" rpy="0 0 0"/>
    <geometry>
      <mesh filename="package://Robot_description/meshes/BR_R5_1.stl" scale="0.001 0.001 0.001"/>
    </geometry>
  </collision>
</link>

<link name="BR_R6_1">
  <inertial>
    <origin xyz="0.010682156366847245 0.016619499101691748 0.01273104961297547" rpy="0 0 0"/>
    <mass value="0.07897141474580419"/>
    <inertia ixx="1.1e-05" iyy="8e-06" izz="1e-05" ixy="-3e-06" iyz="-4e-06" ixz="-2e-06"/>
  </inertial>
  <visual>
    <origin xyz="0.174037 0.176678 0.012844" rpy="0 0 0"/>
    <geometry>
      <mesh filename="package://Robot_description/meshes/BR_R6_1.stl" scale="0.001 0.001 0.001"/>
    </geometry>
    <material name="black"/>
  </visual>
  <collision>
    <origin xyz="0.174037 0.176678 0.012844" rpy="0 0 0"/>
    <geometry>
      <mesh filename="package://Robot_description/meshes/BR_R6_1.stl" scale="0.001 0.001 0.001"/>
    </geometry>
  </collision>
</link>

<link name="BR_R7_1">
  <inertial>
    <origin xyz="0.016366693234100255 0.01661949910166327 0.0028857416909925243" rpy="0 0 0"/>
    <mass value="0.078971414745804"/>
    <inertia ixx="8e-06" iyy="8e-06" izz="1.3e-05" ixy="-5e-06" iyz="-1e-06" ixz="-1e-06"/>
  </inertial>
  <visual>
    <origin xyz="0.155863 0.176678 -0.010778" rpy="0 0 0"/>
    <geometry>
      <mesh filename="package://Robot_description/meshes/BR_R7_1.stl" scale="0.001 0.001 0.001"/>
    </geometry>
    <material name="black"/>
  </visual>
  <collision>
    <origin xyz="0.155863 0.176678 -0.010778" rpy="0 0 0"/>
    <geometry>
      <mesh filename="package://Robot_description/meshes/BR_R7_1.stl" scale="0.001 0.001 0.001"/>
    </geometry>
  </collision>
</link>

<link name="BR_R8_1">
  <inertial>
    <origin xyz="0.01439287979244154 0.016619499101653862 -0.008309671781580975" rpy="0 0 0"/>
    <mass value="0.07897141474580414"/>
    <inertia ixx="9e-06" iyy="8e-06" izz="1.2e-05" ixy="-4e-06" iyz="2e-06" ixz="2e-06"/>
  </inertial>
  <visual>
    <origin xyz="0.126757 0.176678 -0.017191" rpy="0 0 0"/>
    <geometry>
      <mesh filename="package://Robot_description/meshes/BR_R8_1.stl" scale="0.001 0.001 0.001"/>
    </geometry>
    <material name="black"/>
  </visual>
  <collision>
    <origin xyz="0.126757 0.176678 -0.017191" rpy="0 0 0"/>
    <geometry>
      <mesh filename="package://Robot_description/meshes/BR_R8_1.stl" scale="0.001 0.001 0.001"/>
    </geometry>
  </collision>
</link>

<link name="BR_R9_1">
  <inertial>
    <origin xyz="0.005684264410537876 0.01661949910166599 -0.015616446390367135" rpy="0 0 0"/>
    <mass value="0.07897141474580434"/>
    <inertia ixx="1.2e-05" iyy="8e-06" izz="9e-06" ixy="-2e-06" iyz="4e-06" ixz="1e-06"/>
  </inertial>
  <visual>
    <origin xyz="0.100338 0.176678 -0.003394" rpy="0 0 0"/>
    <geometry>
      <mesh filename="package://Robot_description/meshes/BR_R9_1.stl" scale="0.001 0.001 0.001"/>
    </geometry>
    <material name="black"/>
  </visual>
  <collision>
    <origin xyz="0.100338 0.176678 -0.003394" rpy="0 0 0"/>
    <geometry>
      <mesh filename="package://Robot_description/meshes/BR_R9_1.stl" scale="0.001 0.001 0.001"/>
    </geometry>
  </collision>
</link>

<link name="TR_R1_1">
  <inertial>
    <origin xyz="-0.0056842644105380286 0.016619499101665935 -0.01561644639036737" rpy="0 0 0"/>
    <mass value="0.07897141474580824"/>
    <inertia ixx="1.2e-05" iyy="8e-06" izz="9e-06" ixy="2e-06" iyz="4e-06" ixz="-1e-06"/>
  </inertial>
  <visual>
    <origin xyz="-0.100338 0.176678 -0.003394" rpy="0 0 0"/>
    <geometry>
      <mesh filename="package://Robot_description/meshes/TR_R1_1.stl" scale="0.001 0.001 0.001"/>
    </geometry>
    <material name="black"/>
  </visual>
  <collision>
    <origin xyz="-0.100338 0.176678 -0.003394" rpy="0 0 0"/>
    <geometry>
      <mesh filename="package://Robot_description/meshes/TR_R1_1.stl" scale="0.001 0.001 0.001"/>
    </geometry>
  </collision>
</link>

<link name="TR_R2_1">
  <inertial>
    <origin xyz="-0.01439287979244154 0.016619499101653945 -0.008309671781581538" rpy="0 0 0"/>
    <mass value="0.07897141474580814"/>
    <inertia ixx="9e-06" iyy="8e-06" izz="1.2e-05" ixy="4e-06" iyz="2e-06" ixz="-2e-06"/>
  </inertial>
  <visual>
    <origin xyz="-0.126757 0.176678 -0.017191" rpy="0 0 0"/>
    <geometry>
      <mesh filename="package://Robot_description/meshes/TR_R2_1.stl" scale="0.001 0.001 0.001"/>
    </geometry>
    <material name="black"/>
  </visual>
  <collision>
    <origin xyz="-0.126757 0.176678 -0.017191" rpy="0 0 0"/>
    <geometry>
      <mesh filename="package://Robot_description/meshes/TR_R2_1.stl" scale="0.001 0.001 0.001"/>
    </geometry>
  </collision>
</link>

<link name="TR_R3_1">
  <inertial>
    <origin xyz="-0.016366693234100477 0.016619499101663965 0.0028857416909923283" rpy="0 0 0"/>
    <mass value="0.078971414745808"/>
    <inertia ixx="8e-06" iyy="8e-06" izz="1.3e-05" ixy="5e-06" iyz="-1e-06" ixz="1e-06"/>
  </inertial>
  <visual>
    <origin xyz="-0.155863 0.176678 -0.010778" rpy="0 0 0"/>
    <geometry>
      <mesh filename="package://Robot_description/meshes/TR_R3_1.stl" scale="0.001 0.001 0.001"/>
    </geometry>
    <material name="black"/>
  </visual>
  <collision>
    <origin xyz="-0.155863 0.176678 -0.010778" rpy="0 0 0"/>
    <geometry>
      <mesh filename="package://Robot_description/meshes/TR_R3_1.stl" scale="0.001 0.001 0.001"/>
    </geometry>
  </collision>
</link>

<link name="TR_R4_1">
  <inertial>
    <origin xyz="-0.010682156366847051 0.016619499101691942 0.01273104961297553" rpy="0 0 0"/>
    <mass value="0.07897141474580803"/>
    <inertia ixx="1.1e-05" iyy="8e-06" izz="1e-05" ixy="3e-06" iyz="-4e-06" ixz="2e-06"/>
  </inertial>
  <visual>
    <origin xyz="-0.174037 0.176678 0.012844" rpy="0 0 0"/>
    <geometry>
      <mesh filename="package://Robot_description/meshes/TR_R4_1.stl" scale="0.001 0.001 0.001"/>
    </geometry>
    <material name="black"/>
  </visual>
  <collision>
    <origin xyz="-0.174037 0.176678 0.012844" rpy="0 0 0"/>
    <geometry>
      <mesh filename="package://Robot_description/meshes/TR_R4_1.stl" scale="0.001 0.001 0.001"/>
    </geometry>
  </collision>
</link>

<link name="TR_R5_1">
  <inertial>
    <origin xyz="5.625105450879353e-08 0.016619499101712315 0.01661851931853102" rpy="0 0 0"/>
    <mass value="0.07897141474580813"/>
    <inertia ixx="1.3e-05" iyy="8e-06" izz="8e-06" ixy="0.0" iyz="-5e-06" ixz="-0.0"/>
  </inertial>
  <visual>
    <origin xyz="-0.172776 0.176678 0.042621" rpy="0 0 0"/>
    <geometry>
      <mesh filename="package://Robot_description/meshes/TR_R5_1.stl" scale="0.001 0.001 0.001"/>
    </geometry>
    <material name="black"/>
  </visual>
  <collision>
    <origin xyz="-0.172776 0.176678 0.042621" rpy="0 0 0"/>
    <geometry>
      <mesh filename="package://Robot_description/meshes/TR_R5_1.stl" scale="0.001 0.001 0.001"/>
    </geometry>
  </collision>
</link>

<link name="TR_R6_1">
  <inertial>
    <origin xyz="0.010682654530559721 0.016619499101727886 0.012731149762510746" rpy="0 0 0"/>
    <mass value="0.07897141474580806"/>
    <inertia ixx="1.1e-05" iyy="8e-06" izz="1e-05" ixy="-3e-06" iyz="-4e-06" ixz="-2e-06"/>
  </inertial>
  <visual>
    <origin xyz="-0.152669 0.176678 0.064622" rpy="0 0 0"/>
    <geometry>
      <mesh filename="package://Robot_description/meshes/TR_R6_1.stl" scale="0.001 0.001 0.001"/>
    </geometry>
    <material name="black"/>
  </visual>
  <collision>
    <origin xyz="-0.152669 0.176678 0.064622" rpy="0 0 0"/>
    <geometry>
      <mesh filename="package://Robot_description/meshes/TR_R6_1.stl" scale="0.001 0.001 0.001"/>
    </geometry>
  </collision>
</link>

<link name="TR_R7_1">
  <inertial>
    <origin xyz="0.016366420777257126 0.016619499101732133 0.0028853967773263406" rpy="0 0 0"/>
    <mass value="0.07897141474580818"/>
    <inertia ixx="8e-06" iyy="8e-06" izz="1.3e-05" ixy="-5e-06" iyz="-1e-06" ixz="-1e-06"/>
  </inertial>
  <visual>
    <origin xyz="-0.123125 0.176678 0.06855" rpy="0 0 0"/>
    <geometry>
      <mesh filename="package://Robot_description/meshes/TR_R7_1.stl" scale="0.001 0.001 0.001"/>
    </geometry>
    <material name="black"/>
  </visual>
  <collision>
    <origin xyz="-0.123125 0.176678 0.06855" rpy="0 0 0"/>
    <geometry>
      <mesh filename="package://Robot_description/meshes/TR_R7_1.stl" scale="0.001 0.001 0.001"/>
    </geometry>
  </collision>
</link>

<link name="TR_R8_1">
  <inertial>
    <origin xyz="0.014392823541257996 0.016619499101708374 -0.008309847537017946" rpy="0 0 0"/>
    <mass value="0.07897141474580821"/>
    <inertia ixx="9e-06" iyy="8e-06" izz="1.2e-05" ixy="-4e-06" iyz="2e-06" ixz="2e-06"/>
  </inertial>
  <visual>
    <origin xyz="-0.097967 0.176678 0.052569" rpy="0 0 0"/>
    <geometry>
      <mesh filename="package://Robot_description/meshes/TR_R8_1.stl" scale="0.001 0.001 0.001"/>
    </geometry>
    <material name="black"/>
  </visual>
  <collision>
    <origin xyz="-0.097967 0.176678 0.052569" rpy="0 0 0"/>
    <geometry>
      <mesh filename="package://Robot_description/meshes/TR_R8_1.stl" scale="0.001 0.001 0.001"/>
    </geometry>
  </collision>
</link>

<link name="TR_R9_1">
  <inertial>
    <origin xyz="0.005684038703412747 0.016619499101683533 -0.015616891453574432" rpy="0 0 0"/>
    <mass value="0.07897141474580799"/>
    <inertia ixx="1.2e-05" iyy="8e-06" izz="9e-06" ixy="-2e-06" iyz="4e-06" ixz="1e-06"/>
  </inertial>
  <visual>
    <origin xyz="-0.088968 0.176678 0.024156" rpy="0 0 0"/>
    <geometry>
      <mesh filename="package://Robot_description/meshes/TR_R9_1.stl" scale="0.001 0.001 0.001"/>
    </geometry>
    <material name="black"/>
  </visual>
  <collision>
    <origin xyz="-0.088968 0.176678 0.024156" rpy="0 0 0"/>
    <geometry>
      <mesh filename="package://Robot_description/meshes/TR_R9_1.stl" scale="0.001 0.001 0.001"/>
    </geometry>
  </collision>
</link>

<link name="BL_R1_1">
  <inertial>
    <origin xyz="0.005684264410538167 -0.016619499101665908 -0.01561644639036736" rpy="0 0 0"/>
    <mass value="0.07897141474580824"/>
    <inertia ixx="1.2e-05" iyy="8e-06" izz="9e-06" ixy="2e-06" iyz="-4e-06" ixz="1e-06"/>
  </inertial>
  <visual>
    <origin xyz="0.100338 -0.176678 -0.003394" rpy="0 0 0"/>
    <geometry>
      <mesh filename="package://Robot_description/meshes/BL_R1_1.stl" scale="0.001 0.001 0.001"/>
    </geometry>
    <material name="black"/>
  </visual>
  <collision>
    <origin xyz="0.100338 -0.176678 -0.003394" rpy="0 0 0"/>
    <geometry>
      <mesh filename="package://Robot_description/meshes/BL_R1_1.stl" scale="0.001 0.001 0.001"/>
    </geometry>
  </collision>
</link>

<link name="BL_R2_1">
  <inertial>
    <origin xyz="-0.005684038703412608 -0.016619499101683505 -0.015616891453574418" rpy="0 0 0"/>
    <mass value="0.07897141474580799"/>
    <inertia ixx="1.2e-05" iyy="8e-06" izz="9e-06" ixy="-2e-06" iyz="-4e-06" ixz="-1e-06"/>
  </inertial>
  <visual>
    <origin xyz="0.088968 -0.176678 0.024156" rpy="0 0 0"/>
    <geometry>
      <mesh filename="package://Robot_description/meshes/BL_R2_1.stl" scale="0.001 0.001 0.001"/>
    </geometry>
    <material name="black"/>
  </visual>
  <collision>
    <origin xyz="0.088968 -0.176678 0.024156" rpy="0 0 0"/>
    <geometry>
      <mesh filename="package://Robot_description/meshes/BL_R2_1.stl" scale="0.001 0.001 0.001"/>
    </geometry>
  </collision>
</link>

<link name="BL_R3_1">
  <inertial>
    <origin xyz="-0.014392823541257885 -0.01661949910170829 -0.008309847537017932" rpy="0 0 0"/>
    <mass value="0.07897141474580821"/>
    <inertia ixx="9e-06" iyy="8e-06" izz="1.2e-05" ixy="-4e-06" iyz="-2e-06" ixz="-2e-06"/>
  </inertial>
  <visual>
    <origin xyz="0.097967 -0.176678 0.052569" rpy="0 0 0"/>
    <geometry>
      <mesh filename="package://Robot_description/meshes/BL_R3_1.stl" scale="0.001 0.001 0.001"/>
    </geometry>
    <material name="black"/>
  </visual>
  <collision>
    <origin xyz="0.097967 -0.176678 0.052569" rpy="0 0 0"/>
    <geometry>
      <mesh filename="package://Robot_description/meshes/BL_R3_1.stl" scale="0.001 0.001 0.001"/>
    </geometry>
  </collision>
</link>

<link name="BL_R4_1">
  <inertial>
    <origin xyz="-0.01636642077725707 -0.016619499101732077 0.0028853967773263545" rpy="0 0 0"/>
    <mass value="0.07897141474580818"/>
    <inertia ixx="8e-06" iyy="8e-06" izz="1.3e-05" ixy="-5e-06" iyz="1e-06" ixz="1e-06"/>
  </inertial>
  <visual>
    <origin xyz="0.123125 -0.176678 0.06855" rpy="0 0 0"/>
    <geometry>
      <mesh filename="package://Robot_description/meshes/BL_R4_1.stl" scale="0.001 0.001 0.001"/>
    </geometry>
    <material name="black"/>
  </visual>
  <collision>
    <origin xyz="0.123125 -0.176678 0.06855" rpy="0 0 0"/>
    <geometry>
      <mesh filename="package://Robot_description/meshes/BL_R4_1.stl" scale="0.001 0.001 0.001"/>
    </geometry>
  </collision>
</link>

<link name="BL_R5_1">
  <inertial>
    <origin xyz="-0.010682654530559665 -0.01661949910172772 0.012731149762510767" rpy="0 0 0"/>
    <mass value="0.07897141474580806"/>
    <inertia ixx="1.1e-05" iyy="8e-06" izz="1e-05" ixy="-3e-06" iyz="4e-06" ixz="2e-06"/>
  </inertial>
  <visual>
    <origin xyz="0.152669 -0.176678 0.064622" rpy="0 0 0"/>
    <geometry>
      <mesh filename="package://Robot_description/meshes/BL_R5_1.stl" scale="0.001 0.001 0.001"/>
    </geometry>
    <material name="black"/>
  </visual>
  <collision>
    <origin xyz="0.152669 -0.176678 0.064622" rpy="0 0 0"/>
    <geometry>
      <mesh filename="package://Robot_description/meshes/BL_R5_1.stl" scale="0.001 0.001 0.001"/>
    </geometry>
  </collision>
</link>

<link name="BL_R6_1">
  <inertial>
    <origin xyz="-5.625105450879353e-08 -0.016619499101712176 0.016618519318531026" rpy="0 0 0"/>
    <mass value="0.07897141474580813"/>
    <inertia ixx="1.3e-05" iyy="8e-06" izz="8e-06" ixy="0.0" iyz="5e-06" ixz="0.0"/>
  </inertial>
  <visual>
    <origin xyz="0.172776 -0.176678 0.042621" rpy="0 0 0"/>
    <geometry>
      <mesh filename="package://Robot_description/meshes/BL_R6_1.stl" scale="0.001 0.001 0.001"/>
    </geometry>
    <material name="black"/>
  </visual>
  <collision>
    <origin xyz="0.172776 -0.176678 0.042621" rpy="0 0 0"/>
    <geometry>
      <mesh filename="package://Robot_description/meshes/BL_R6_1.stl" scale="0.001 0.001 0.001"/>
    </geometry>
  </collision>
</link>

<link name="BL_R7_1">
  <inertial>
    <origin xyz="0.010682156366847051 -0.01661949910169186 0.012731049612975538" rpy="0 0 0"/>
    <mass value="0.07897141474580803"/>
    <inertia ixx="1.1e-05" iyy="8e-06" izz="1e-05" ixy="3e-06" iyz="4e-06" ixz="-2e-06"/>
  </inertial>
  <visual>
    <origin xyz="0.174037 -0.176678 0.012844" rpy="0 0 0"/>
    <geometry>
      <mesh filename="package://Robot_description/meshes/BL_R7_1.stl" scale="0.001 0.001 0.001"/>
    </geometry>
    <material name="black"/>
  </visual>
  <collision>
    <origin xyz="0.174037 -0.176678 0.012844" rpy="0 0 0"/>
    <geometry>
      <mesh filename="package://Robot_description/meshes/BL_R7_1.stl" scale="0.001 0.001 0.001"/>
    </geometry>
  </collision>
</link>

<link name="BL_R8_1">
  <inertial>
    <origin xyz="0.016366693234100532 -0.016619499101663854 0.002885741690992337" rpy="0 0 0"/>
    <mass value="0.078971414745808"/>
    <inertia ixx="8e-06" iyy="8e-06" izz="1.3e-05" ixy="5e-06" iyz="1e-06" ixz="-1e-06"/>
  </inertial>
  <visual>
    <origin xyz="0.155863 -0.176678 -0.010778" rpy="0 0 0"/>
    <geometry>
      <mesh filename="package://Robot_description/meshes/BL_R8_1.stl" scale="0.001 0.001 0.001"/>
    </geometry>
    <material name="black"/>
  </visual>
  <collision>
    <origin xyz="0.155863 -0.176678 -0.010778" rpy="0 0 0"/>
    <geometry>
      <mesh filename="package://Robot_description/meshes/BL_R8_1.stl" scale="0.001 0.001 0.001"/>
    </geometry>
  </collision>
</link>

<link name="BL_R9_1">
  <inertial>
    <origin xyz="0.014392879792441651 -0.016619499101653917 -0.00830967178158153" rpy="0 0 0"/>
    <mass value="0.07897141474580814"/>
    <inertia ixx="9e-06" iyy="8e-06" izz="1.2e-05" ixy="4e-06" iyz="-2e-06" ixz="2e-06"/>
  </inertial>
  <visual>
    <origin xyz="0.126757 -0.176678 -0.017191" rpy="0 0 0"/>
    <geometry>
      <mesh filename="package://Robot_description/meshes/BL_R9_1.stl" scale="0.001 0.001 0.001"/>
    </geometry>
    <material name="black"/>
  </visual>
  <collision>
    <origin xyz="0.126757 -0.176678 -0.017191" rpy="0 0 0"/>
    <geometry>
      <mesh filename="package://Robot_description/meshes/BL_R9_1.stl" scale="0.001 0.001 0.001"/>
    </geometry>
  </collision>
</link>

<link name="Wheel_TL_1">
  <inertial>
    <origin xyz="5.332548975722773e-07 0.04201272498512379 -8.368614828890841e-11" rpy="0 0 0"/>
    <mass value="1.1609308119154003"/>
    <inertia ixx="0.000706" iyy="0.000721" izz="0.000706" ixy="-0.0" iyz="-0.0" ixz="-0.0"/>
  </inertial>
  <visual>
    <origin xyz="-0.1325 -0.115065 0.026" rpy="0 0 0"/>
    <geometry>
      <mesh filename="package://Robot_description/meshes/Wheel_TL_1.stl" scale="0.001 0.001 0.001"/>
    </geometry>
    <material name="blue"/>
  </visual>
  <collision>
    <origin xyz="-0.1325 -0.115065 0.026" rpy="0 0 0"/>
    <geometry>
      <mesh filename="package://Robot_description/meshes/Wheel_TL_1.stl" scale="0.001 0.001 0.001"/>
    </geometry>
  </collision>
</link>

<link name="Wheel_BR_1">
  <inertial>
    <origin xyz="-5.332548975722773e-07 -0.04201272498512379 -8.368614828890841e-11" rpy="0 0 0"/>
    <mass value="1.1609308119154003"/>
    <inertia ixx="0.000706" iyy="0.000721" izz="0.000706" ixy="-0.0" iyz="0.0" ixz="0.0"/>
  </inertial>
  <visual>
    <origin xyz="0.1325 0.115065 0.026" rpy="0 0 0"/>
    <geometry>
      <mesh filename="package://Robot_description/meshes/Wheel_BR_1.stl" scale="0.001 0.001 0.001"/>
    </geometry>
    <material name="blue"/>
  </visual>
  <collision>
    <origin xyz="0.1325 0.115065 0.026" rpy="0 0 0"/>
    <geometry>
      <mesh filename="package://Robot_description/meshes/Wheel_BR_1.stl" scale="0.001 0.001 0.001"/>
    </geometry>
  </collision>
</link>

<link name="Wheel_TR_1">
  <inertial>
    <origin xyz="2.566130756415097e-06 -0.04201272469318337 -4.444462572000818e-06" rpy="0 0 0"/>
    <mass value="1.1609308119154"/>
    <inertia ixx="0.000706" iyy="0.000721" izz="0.000706" ixy="0.0" iyz="0.0" ixz="0.0"/>
  </inertial>
  <visual>
    <origin xyz="-0.1325 0.115065 0.026" rpy="0 0 0"/>
    <geometry>
      <mesh filename="package://Robot_description/meshes/Wheel_TR_1.stl" scale="0.001 0.001 0.001"/>
    </geometry>
    <material name="blue"/>
  </visual>
  <collision>
    <origin xyz="-0.1325 0.115065 0.026" rpy="0 0 0"/>
    <geometry>
      <mesh filename="package://Robot_description/meshes/Wheel_TR_1.stl" scale="0.001 0.001 0.001"/>
    </geometry>
  </collision>
</link>

<link name="Wheel_BL_1">
  <inertial>
    <origin xyz="-2.566130756415097e-06 0.04201272469318337 -4.444462572000818e-06" rpy="0 0 0"/>
    <mass value="1.1609308119154"/>
    <inertia ixx="0.000706" iyy="0.000721" izz="0.000706" ixy="0.0" iyz="-0.0" ixz="-0.0"/>
  </inertial>
  <visual>
    <origin xyz="0.1325 -0.115065 0.026" rpy="0 0 0"/>
    <geometry>
      <mesh filename="package://Robot_description/meshes/Wheel_BL_1.stl" scale="0.001 0.001 0.001"/>
    </geometry>
    <material name="blue"/>
  </visual>
  <collision>
    <origin xyz="0.1325 -0.115065 0.026" rpy="0 0 0"/>
    <geometry>
      <mesh filename="package://Robot_description/meshes/Wheel_BL_1.stl" scale="0.001 0.001 0.001"/>
    </geometry>
  </collision>
</link>

<joint name="TL_R1_joint" type="continuous">
  <origin xyz="-0.005743 0.061613 0.043191" rpy="0 0 0"/>
  <parent link="Wheel_TL_1"/>
  <child link="TL_R1_1"/>
  <axis xyz="-0.612372 -0.707107 -0.353553"/>
</joint>

<joint name="TL_R2_joint" type="continuous">
  <origin xyz="0.023363 0.061613 0.036778" rpy="0 0 0"/>
  <parent link="Wheel_TL_1"/>
  <child link="TL_R2_1"/>
  <axis xyz="-0.696364 -0.707107 0.122788"/>
</joint>

<joint name="TL_R3_joint" type="continuous">
  <origin xyz="0.041537 0.061613 0.013156" rpy="0 0 0"/>
  <parent link="Wheel_TL_1"/>
  <child link="TL_R3_1"/>
  <axis xyz="-0.454519 -0.707107 0.541675"/>
</joint>

<joint name="TL_R4_joint" type="continuous">
  <origin xyz="0.040276 0.061613 -0.016621" rpy="0 0 0"/>
  <parent link="Wheel_TL_1"/>
  <child link="TL_R4_1"/>
  <axis xyz="0.0 -0.707107 0.707107"/>
</joint>

<joint name="TL_R5_joint" type="continuous">
  <origin xyz="0.020169 0.061613 -0.038622" rpy="0 0 0"/>
  <parent link="Wheel_TL_1"/>
  <child link="TL_R5_1"/>
  <axis xyz="0.454519 -0.707107 0.541675"/>
</joint>

<joint name="TL_R6_joint" type="continuous">
  <origin xyz="-0.009375 0.061613 -0.04255" rpy="0 0 0"/>
  <parent link="Wheel_TL_1"/>
  <child link="TL_R6_1"/>
  <axis xyz="0.696364 -0.707107 0.122788"/>
</joint>

<joint name="TL_R7_joint" type="continuous">
  <origin xyz="-0.034533 0.061613 -0.026569" rpy="0 0 0"/>
  <parent link="Wheel_TL_1"/>
  <child link="TL_R7_1"/>
  <axis xyz="0.612372 -0.707107 -0.353553"/>
</joint>

<joint name="TL_R8_joint" type="continuous">
  <origin xyz="-0.043532 0.061613 0.001844" rpy="0 0 0"/>
  <parent link="Wheel_TL_1"/>
  <child link="TL_R8_1"/>
  <axis xyz="0.241845 -0.707107 -0.664463"/>
</joint>

<joint name="TL_R9_joint" type="continuous">
  <origin xyz="-0.032162 0.061613 0.029394" rpy="0 0 0"/>
  <parent link="Wheel_TL_1"/>
  <child link="TL_R9_1"/>
  <axis xyz="-0.241845 -0.707107 -0.664463"/>
</joint>

<joint name="BR_R1_joint" type="continuous">
  <origin xyz="0.043532 -0.061613 0.001844" rpy="0 0 0"/>
  <parent link="Wheel_BR_1"/>
  <child link="BR_R1_1"/>
  <axis xyz="-0.241845 0.707107 -0.664463"/>
</joint>

<joint name="BR_R2_joint" type="continuous">
  <origin xyz="0.034533 -0.061613 -0.026569" rpy="0 0 0"/>
  <parent link="Wheel_BR_1"/>
  <child link="BR_R2_1"/>
  <axis xyz="-0.612372 0.707107 -0.353553"/>
</joint>

<joint name="BR_R3_joint" type="continuous">
  <origin xyz="0.009375 -0.061613 -0.04255" rpy="0 0 0"/>
  <parent link="Wheel_BR_1"/>
  <child link="BR_R3_1"/>
  <axis xyz="-0.696364 0.707107 0.122788"/>
</joint>

<joint name="BR_R4_joint" type="continuous">
  <origin xyz="-0.020169 -0.061613 -0.038622" rpy="0 0 0"/>
  <parent link="Wheel_BR_1"/>
  <child link="BR_R4_1"/>
  <axis xyz="-0.454519 0.707107 0.541675"/>
</joint>

<joint name="BR_R5_joint" type="continuous">
  <origin xyz="-0.040276 -0.061613 -0.016621" rpy="0 0 0"/>
  <parent link="Wheel_BR_1"/>
  <child link="BR_R5_1"/>
  <axis xyz="-0.0 0.707107 0.707107"/>
</joint>

<joint name="BR_R6_joint" type="continuous">
  <origin xyz="-0.041537 -0.061613 0.013156" rpy="0 0 0"/>
  <parent link="Wheel_BR_1"/>
  <child link="BR_R6_1"/>
  <axis xyz="0.454519 0.707107 0.541675"/>
</joint>

<joint name="BR_R7_joint" type="continuous">
  <origin xyz="-0.023363 -0.061613 0.036778" rpy="0 0 0"/>
  <parent link="Wheel_BR_1"/>
  <child link="BR_R7_1"/>
  <axis xyz="0.696364 0.707107 0.122788"/>
</joint>

<joint name="BR_R8_joint" type="continuous">
  <origin xyz="0.005743 -0.061613 0.043191" rpy="0 0 0"/>
  <parent link="Wheel_BR_1"/>
  <child link="BR_R8_1"/>
  <axis xyz="0.612372 0.707107 -0.353553"/>
</joint>

<joint name="BR_R9_joint" type="continuous">
  <origin xyz="0.032162 -0.061613 0.029394" rpy="0 0 0"/>
  <parent link="Wheel_BR_1"/>
  <child link="BR_R9_1"/>
  <axis xyz="0.241845 0.707107 -0.664463"/>
</joint>

<joint name="TR_R1_joint" type="continuous">
  <origin xyz="-0.032162 -0.061613 0.029394" rpy="0 0 0"/>
  <parent link="Wheel_TR_1"/>
  <child link="TR_R1_1"/>
  <axis xyz="0.241845 -0.707107 0.664463"/>
</joint>

<joint name="TR_R2_joint" type="continuous">
  <origin xyz="-0.005743 -0.061613 0.043191" rpy="0 0 0"/>
  <parent link="Wheel_TR_1"/>
  <child link="TR_R2_1"/>
  <axis xyz="0.612372 -0.707107 0.353553"/>
</joint>

<joint name="TR_R3_joint" type="continuous">
  <origin xyz="0.023363 -0.061613 0.036778" rpy="0 0 0"/>
  <parent link="Wheel_TR_1"/>
  <child link="TR_R3_1"/>
  <axis xyz="0.696364 -0.707107 -0.122788"/>
</joint>

<joint name="TR_R4_joint" type="continuous">
  <origin xyz="0.041537 -0.061613 0.013156" rpy="0 0 0"/>
  <parent link="Wheel_TR_1"/>
  <child link="TR_R4_1"/>
  <axis xyz="0.454519 -0.707107 -0.541675"/>
</joint>

<joint name="TR_R5_joint" type="continuous">
  <origin xyz="0.040276 -0.061613 -0.016621" rpy="0 0 0"/>
  <parent link="Wheel_TR_1"/>
  <child link="TR_R5_1"/>
  <axis xyz="-0.0 -0.707107 -0.707107"/>
</joint>

<joint name="TR_R6_joint" type="continuous">
  <origin xyz="0.020169 -0.061613 -0.038622" rpy="0 0 0"/>
  <parent link="Wheel_TR_1"/>
  <child link="TR_R6_1"/>
  <axis xyz="-0.454519 -0.707107 -0.541675"/>
</joint>

<joint name="TR_R7_joint" type="continuous">
  <origin xyz="-0.009375 -0.061613 -0.04255" rpy="0 0 0"/>
  <parent link="Wheel_TR_1"/>
  <child link="TR_R7_1"/>
  <axis xyz="-0.696364 -0.707107 -0.122788"/>
</joint>

<joint name="TR_R8_joint" type="continuous">
  <origin xyz="-0.034533 -0.061613 -0.026569" rpy="0 0 0"/>
  <parent link="Wheel_TR_1"/>
  <child link="TR_R8_1"/>
  <axis xyz="-0.612372 -0.707107 0.353553"/>
</joint>

<joint name="TR_R9_joint" type="continuous">
  <origin xyz="-0.043532 -0.061613 0.001844" rpy="0 0 0"/>
  <parent link="Wheel_TR_1"/>
  <child link="TR_R9_1"/>
  <axis xyz="-0.241845 -0.707107 0.664463"/>
</joint>

<joint name="BL_R1_joint" type="continuous">
  <origin xyz="0.032162 0.061613 0.029394" rpy="0 0 0"/>
  <parent link="Wheel_BL_1"/>
  <child link="BL_R1_1"/>
  <axis xyz="-0.241845 0.707107 0.664463"/>
</joint>

<joint name="BL_R2_joint" type="continuous">
  <origin xyz="0.043532 0.061613 0.001844" rpy="0 0 0"/>
  <parent link="Wheel_BL_1"/>
  <child link="BL_R2_1"/>
  <axis xyz="0.241845 0.707107 0.664463"/>
</joint>

<joint name="BL_R3_joint" type="continuous">
  <origin xyz="0.034533 0.061613 -0.026569" rpy="0 0 0"/>
  <parent link="Wheel_BL_1"/>
  <child link="BL_R3_1"/>
  <axis xyz="0.612372 0.707107 0.353553"/>
</joint>

<joint name="BL_R4_joint" type="continuous">
  <origin xyz="0.009375 0.061613 -0.04255" rpy="0 0 0"/>
  <parent link="Wheel_BL_1"/>
  <child link="BL_R4_1"/>
  <axis xyz="0.696364 0.707107 -0.122788"/>
</joint>

<joint name="BL_R5_joint" type="continuous">
  <origin xyz="-0.020169 0.061613 -0.038622" rpy="0 0 0"/>
  <parent link="Wheel_BL_1"/>
  <child link="BL_R5_1"/>
  <axis xyz="0.454519 0.707107 -0.541675"/>
</joint>

<joint name="BL_R6_joint" type="continuous">
  <origin xyz="-0.040276 0.061613 -0.016621" rpy="0 0 0"/>
  <parent link="Wheel_BL_1"/>
  <child link="BL_R6_1"/>
  <axis xyz="0.0 0.707107 -0.707107"/>
</joint>

<joint name="BL_R7_joint" type="continuous">
  <origin xyz="-0.041537 0.061613 0.013156" rpy="0 0 0"/>
  <parent link="Wheel_BL_1"/>
  <child link="BL_R7_1"/>
  <axis xyz="-0.454519 0.707107 -0.541675"/>
</joint>

<joint name="BL_R8_joint" type="continuous">
  <origin xyz="-0.023363 0.061613 0.036778" rpy="0 0 0"/>
  <parent link="Wheel_BL_1"/>
  <child link="BL_R8_1"/>
  <axis xyz="-0.696364 0.707107 -0.122788"/>
</joint>

<joint name="BL_R9_joint" type="continuous">
  <origin xyz="0.005743 0.061613 0.043191" rpy="0 0 0"/>
  <parent link="Wheel_BL_1"/>
  <child link="BL_R9_1"/>
  <axis xyz="-0.612372 0.707107 0.353553"/>
</joint>

<joint name="Wheel_TL_joint" type="continuous">
  <origin xyz="0.1325 0.115065 -0.026" rpy="0 0 0"/>
  <parent link="base_link"/>
  <child link="Wheel_TL_1"/>
  <axis xyz="0.0 1.0 0.0"/>
</joint>

<joint name="Wheel_BR_joint" type="continuous">
  <origin xyz="-0.1325 -0.115065 -0.026" rpy="0 0 0"/>
  <parent link="base_link"/>
  <child link="Wheel_BR_1"/>
  <axis xyz="0.0 1.0 -0.0"/>
</joint>

<joint name="Wheel_TR_joint" type="continuous">
  <origin xyz="0.1325 -0.115065 -0.026" rpy="0 0 0"/>
  <parent link="base_link"/>
  <child link="Wheel_TR_1"/>
  <axis xyz="0.0 -1.0 0.0"/>
</joint>

<joint name="Wheel_BL_joint" type="continuous">
  <origin xyz="-0.1325 0.115065 -0.026" rpy="0 0 0"/>
  <parent link="base_link"/>
  <child link="Wheel_BL_1"/>
  <axis xyz="0.0 1.0 0.0"/>
</joint>

</robot>
